Workbook

Sheet Case-1
A1: N | B1: MAE_Learn | C1: RMSE_Learn | D1: MAPE_Learn | E1: Standard_MAE_Learn | F1: Standard_RMSE_Learn | G1: Standard_MAPE_Learn | H1: np.mean(Z_SATSolver_index_list) | I1: np.std(Z_SATSolver_index_list) | J1: np.mean(Num_Solved_SAT) | K1: np.std(Num_Solved_SAT) | L1: Solved_SAT_Count / (Maxcomb * NumTrail) | M1: np.mean(Ratio_Solved_Component) | N1: np.mean(Ratio_Solved_Initial) | O1: np.mean(Ratio_Solved_Initial_Satisfied) | P1: np.mean(Ratio_Solved_Red) | Q1: np.mean(Ratio_Solved_Red_Satisfied) | R1: np.mean(Ratio_Solved_Tse) | S1: np.mean(Ratio_Solved_Tse_Satisfied) | T1: np.mean(Ratio_Solved_After) | U1: np.mean(Ratio_Solved_After_Satisfied) | V1: MAE_Energy | W1: Ratio of global minimum solutions | X1: Ratio of local minimum solutions | Y1: np.mean(Similarity_list_J_Initial) | Z1: np.std(Similarity_list_J_Initial) | AA1: np.mean(Similarity_list_H_Initial) | AB1: np.std(Similarity_list_H_Initial) | AC1: np.mean(Similarity_list_J_Red) | AD1: np.std(Similarity_list_J_Red) | AE1: np.mean(Similarity_list_H_Red) | AF1: np.std(Similarity_list_H_Red) | AG1: np.mean(Similarity_list_J_Tse) | AH1: np.std(Similarity_list_J_Tse) | AI1: np.mean(Similarity_list_H_Tse) | AJ1: np.std(Similarity_list_H_Tse) | AK1: np.mean(Similarity_list_J_After) | AL1: np.std(Similarity_list_J_After) | AM1: np.mean(Similarity_list_H_After) | AN1: np.std(Similarity_list_H_After)
A2: 6 | B2: 0.20692857 | C2: 0.26783288 | D2: 9.2670635 | E2: 0.33005069 | F2: 0.41941436 | G2: 14.563364 | H2: 0 | I2: 0 | J2: 0 | K2: 0 | L2: 1 | M2: 1 | N2: 1 | O2: 1 | P2: 1 | Q2: 1 | R2: 1 | S2: 1 | T2: 1 | U2: 1 | V2: 0 | W2: 1 | X2: 0 | Y2: 0.38006031 | Z2: 0.11607744 | AA2: 0.074160658 | AB2: 0.029636895 | AC2: 0.38242833 | AD2: 0.12683112 | AE2: 0.0717077 | AF2: 0.014128485 | AG2: 0.40114687 | AH2: 0.1062306 | AI2: 0.067409915 | AJ2: 0.032754929 | AK2: 0.40351489 | AL2: 0.11746164 | AM2: 0.059428013 | AN2: 0.023589775
A3: 12 | B3: 0.58413636 | C3: 0.71969885 | D3: 12.430875 | E3: 0.59987368 | F3: 0.72462287 | G3: 12.125289 | H3: 0 | I3: 0 | J3: 0 | K3: 0 | L3: 1 | M3: 1 | N3: 1 | O3: 1 | P3: 1 | Q3: 1 | R3: 1 | S3: 1 | T3: 1 | U3: 1 | V3: 0 | W3: 1 | X3: 0 | Y3: 0.39884499 | Z3: 0.077197198 | AA3: 0.070033337 | AB3: 0.024067751 | AC3: 0.4051916 | AD3: 0.08325185 | AE3: 0.072408031 | AF3: 0.01499362 | AG3: 0.43080632 | AH3: 0.061149334 | AI3: 0.070993081 | AJ3: 0.033067007 | AK3: 0.43936308 | AL3: 0.064453886 | AM3: 0.070406645 | AN3: 0.037470499
A4: 18 | B4: 0.9136269 | C4: 1.1251492 | D4: 13.302544 | E4: 0.72088887 | F4: 0.85352103 | G4: 10.018104 | H4: 0 | I4: 0 | J4: 0 | K4: 0 | L4: 1 | M4: 1 | N4: 1 | O4: 1 | P4: 1 | Q4: 1 | R4: 1 | S4: 1 | T4: 1 | U4: 1 | V4: 0 | W4: 1 | X4: 0 | Y4: 0.39502933 | Z4: 0.065591499 | AA4: 0.066314275 | AB4: 0.020174006 | AC4: 0.39770818 | AD4: 0.071335476 | AE4: 0.072198366 | AF4: 0.013661478 | AG4: 0.42786676 | AH4: 0.055877443 | AI4: 0.064806481 | AJ4: 0.028705139 | AK4: 0.43335372 | AL4: 0.058689364 | AM4: 0.06684954 | AN4: 0.031626559
A5: 24 | B5: 1.2895562 | C5: 1.5671715 | D5: 14.665718 | E5: 0.8264017 | F5: 0.96467369 | G5: 8.7770788 | H5: 0 | I5: 0 | J5: 0 | K5: 0 | L5: 1 | M5: 1 | N5: 1 | O5: 1 | P5: 1 | Q5: 1 | R5: 1 | S5: 1 | T5: 1 | U5: 1 | V5: 0 | W5: 1 | X5: 0 | Y5: 0.38703975 | Z5: 0.052337987 | AA5: 0.070335969 | AB5: 0.021264162 | AC5: 0.39052784 | AD5: 0.057172827 | AE5: 0.074265315 | AF5: 0.013969019 | AG5: 0.42753891 | AH5: 0.042505301 | AI5: 0.072289357 | AJ5: 0.028316507 | AK5: 0.43326891 | AL5: 0.046734154 | AM5: 0.073817656 | AN5: 0.032497208
A6: 30 | B6: 1.7976594 | C6: 2.1032258 | D6: 16.201592 | E6: 0.92451636 | F6: 1.0067466 | G6: 7.3973772 | H6: 0 | I6: 0 | J6: 0 | K6: 0 | L6: 1 | M6: 1 | N6: 1 | O6: 1 | P6: 1 | Q6: 1 | R6: 1 | S6: 1 | T6: 1 | U6: 1 | V6: 0 | W6: 1 | X6: 0 | Y6: 0.39989837 | Z6: 0.052766797 | AA6: 0.071622213 | AB6: 0.017988649 | AC6: 0.4041133 | AD6: 0.058648061 | AE6: 0.073052524 | AF6: 0.013524692 | AG6: 0.43103743 | AH6: 0.04333041 | AI6: 0.071181185 | AJ6: 0.026836058 | AK6: 0.44061892 | AL6: 0.045236335 | AM6: 0.071003184 | AN6: 0.030676087
A7: 36 | B7: 2.1317682 | C7: 2.4620914 | D7: 16.365887 | E7: 1.0587653 | F7: 1.1639168 | G7: 7.3767778 | H7: 0.01 | I7: 0.099498744 | J7: 0.0154 | K7: 0.12313748 | L7: 0.9846 | M7: 0.99903333 | N7: 0.99917368 | O7: 0.99917368 | P7: 0.99903333 | Q7: 0.99903333 | R7: 0.99924545 | S7: 0.99924545 | T7: 0.99914444 | U7: 0.99914444 | V7: 0.0087115053 | W7: 0.97 | X7: 0.03 | Y7: 0.4006652 | Z7: 0.041602798 | AA7: 0.072369853 | AB7: 0.01684983 | AC7: 0.4053536 | AD7: 0.046808445 | AE7: 0.075356265 | AF7: 0.012940071 | AG7: 0.4356508 | AH7: 0.034362267 | AI7: 0.073809614 | AJ7: 0.025542251 | AK7: 0.44475116 | AL7: 0.035655144 | AM7: 0.075335665 | AN7: 0.031818002
A8: 42 | B8: 2.3435174 | C8: 2.6866121 | D8: 15.342815 | E8: 1.2539344 | F8: 1.3851102 | G8: 7.0046981 | H8: 0.03 | I8: 0.17058722 | J8: 0.0346 | K8: 0.18276444 | L8: 0.9654 | M8: 0.99794829 | N8: 0.99789981 | O8: 0.99789981 | P8: 0.99794829 | Q8: 0.99794829 | R8: 0.99811067 | S8: 0.99811067 | T8: 0.99818262 | U8: 0.99818262 | V8: 0.082293373 | W8: 0.87 | X8: 0.13 | Y8: 0.38930827 | Z8: 0.04178115 | AA8: 0.071627228 | AB8: 0.018202163 | AC8: 0.39248886 | AD8: 0.045994634 | AE8: 0.075714193 | AF8: 0.012855655 | AG8: 0.43361437 | AH8: 0.029894814 | AI8: 0.075731795 | AJ8: 0.029512717 | AK8: 0.44353008 | AL8: 0.029764515 | AM8: 0.078988825 | AN8: 0.033959038
A9: 48 | B9: 3.0349948 | C9: 3.3968739 | D9: 17.216664 | E9: 1.2513729 | F9: 1.288065 | G9: 5.9861266 | H9: 0.04 | I9: 0.19595918 | J9: 0.0704 | K9: 0.27394131 | L9: 0.9344 | M9: 0.99636908 | N9: 0.99583661 | O9: 0.99583661 | P9: 0.99636908 | Q9: 0.99636908 | R9: 0.99657258 | S9: 0.99657258 | T9: 0.99710939 | U9: 0.99710939 | V9: 0.13554212 | W9: 0.78 | X9: 0.22 | Y9: 0.39756549 | Z9: 0.041816311 | AA9: 0.071316768 | AB9: 0.017167944 | AC9: 0.40280206 | AD9: 0.046473039 | AE9: 0.073880829 | AF9: 0.012440013 | AG9: 0.43336344 | AH9: 0.032743969 | AI9: 0.070936867 | AJ9: 0.024358397 | AK9: 0.44357696 | AL9: 0.03285307 | AM9: 0.071389264 | AN9: 0.028031805
A10: 54 | B10: 3.1865045 | C10: 3.539248 | D10: 16.327102 | E10: 1.3711885 | F10: 1.4525881 | G10: 6.1610573 | H10: 0.04 | I10: 0.19595918 | J10: 0.0509 | K10: 0.21979352 | L10: 0.9491 | M10: 0.99760135 | N10: 0.99762186 | O10: 0.99762186 | P10: 0.99760135 | Q10: 0.99760135 | R10: 0.99800217 | S10: 0.99800217 | T10: 0.99799663 | U10: 0.99799663 | V10: 0.1227448 | W10: 0.74 | X10: 0.26 | Y10: 0.39374411 | Z10: 0.042552978 | AA10: 0.070655291 | AB10: 0.016849518 | AC10: 0.39523091 | AD10: 0.046475434 | AE10: 0.074782487 | AF10: 0.011042121 | AG10: 0.43330451 | AH10: 0.03324175 | AI10: 0.071774546 | AJ10: 0.025864967 | AK10: 0.44151974 | AL10: 0.034217548 | AM10: 0.074244072 | AN10: 0.0289046
A11: 60 | B11: 3.7070769 | C11: 4.0822739 | D11: 17.002644 | E11: 1.395597 | F11: 1.397624 | G11: 5.2018972 | H11: 0.06 | I11: 0.23748684 | J11: 0.1277 | K11: 0.38986242 | L11: 0.8926 | M11: 0.99448094 | N11: 0.99345477 | O11: 0.99345477 | P11: 0.99448094 | Q11: 0.99448094 | R11: 0.99493177 | S11: 0.99493177 | T11: 0.99588232 | U11: 0.99588232 | V11: 0.25031136 | W11: 0.59 | X11: 0.41 | Y11: 0.39667092 | Z11: 0.040380819 | AA11: 0.069671181 | AB11: 0.017958022 | AC11: 0.39741493 | AD11: 0.043261666 | AE11: 0.074710839 | AF11: 0.011173678 | AG11: 0.43570182 | AH11: 0.03411979 | AI11: 0.070244059 | AJ11: 0.024394914 | AK11: 0.44275829 | AL11: 0.033884587 | AM11: 0.072723853 | AN11: 0.025189624
A12: 66 | B12: 4.1243739 | C12: 4.4807204 | D12: 17.04693 | E12: 1.6897782 | F12: 1.7367701 | G12: 5.6613109 | H12: 0.18 | I12: 0.38418745 | J12: 0.2716 | K12: 0.5097386 | L12: 0.7583 | M12: 0.98935797 | N12: 0.98838456 | O12: 0.98838456 | P12: 0.98935797 | Q12: 0.98935797 | R12: 0.98986719 | S12: 0.98986719 | T12: 0.99107409 | U12: 0.99107409 | V12: 0.36413254 | W12: 0.51 | X12: 0.49 | Y12: 0.39443866 | Z12: 0.037534636 | AA12: 0.07080736 | AB12: 0.017518117 | AC12: 0.39427261 | AD12: 0.04028454 | AE12: 0.075780831 | AF12: 0.013526541 | AG12: 0.43725457 | AH12: 0.027147388 | AI12: 0.07375471 | AJ12: 0.026053342 | AK12: 0.44305176 | AL12: 0.027507269 | AM12: 0.077019432 | AN12: 0.031835589
A13: 72 | B13: 4.5981307 | C13: 4.9926903 | D13: 17.50119 | E13: 1.7039232 | F13: 1.7453778 | G13: 4.9680302 | H13: 0.14 | I13: 0.34698703 | J13: 0.249 | K13: 0.50714791 | L13: 0.7831 | M13: 0.9910646 | N13: 0.99074504 | O13: 0.99074504 | P13: 0.9910646 | Q13: 0.9910646 | R13: 0.9922922 | S13: 0.9922922 | T13: 0.99285099 | U13: 0.99285099 | V13: 0.4441335 | W13: 0.46 | X13: 0.54 | Y13: 0.39347438 | Z13: 0.034941391 | AA13: 0.068433927 | AB13: 0.014425528 | AC13: 0.39345807 | AD13: 0.038373655 | AE13: 0.076464462 | AF13: 0.011936449 | AG13: 0.43621629 | AH13: 0.027753506 | AI13: 0.070983074 | AJ13: 0.024088594 | AK13: 0.4428658 | AL13: 0.027497201 | AM13: 0.076733662 | AN13: 0.029080269
... A21: 120 | B21: 7.9160603 | C21: 8.3458447 | D21: 18.089254 | E21: 2.4907157 | F21: 2.5249513 | G21: 3.9983546 | H21: 0.32 | I21: 0.58103356 | J21: 0.681 | K21: 0.86766295 | L21: 0.5245 | M21: 0.98452039 | N21: 0.98201121 | O21: 0.98201121 | P21: 0.98452039 | Q21: 0.98452039 | R21: 0.98633153 | S21: 0.98633153 | T21: 0.9886941 | U21: 0.9886941 | V21: 1.2592287 | W21: 0.08 | X21: 0.92 | Y21: 0.39753371 | Z21: 0.030597219 | AA21: 0.06709132 | AB21: 0.014016831 | AC21: 0.397597 | AD21: 0.034813204 | AE21: 0.075467742 | AF21: 0.011388764 | AG21: 0.44053933 | AH21: 0.024253102 | AI21: 0.069224332 | AJ21: 0.022934502 | AK21: 0.4469588 | AL21: 0.026533132 | AM21: 0.075171978 | AN21: 0.02691604

Sheet Case-2
A1: N | B1: MAE_Learn | C1: RMSE_Learn | D1: MAPE_Learn | E1: Standard_MAE_Learn | F1: Standard_RMSE_Learn | G1: Standard_MAPE_Learn | H1: np.mean(Z_SATSolver_index_list) | I1: np.std(Z_SATSolver_index_list) | J1: np.mean(Num_Solved_SAT) | K1: np.std(Num_Solved_SAT) | L1: Solved_SAT_Count / (Maxcomb * NumTrail) | M1: np.mean(Ratio_Solved_Component) | N1: np.mean(Ratio_Solved_Initial) | O1: np.mean(Ratio_Solved_Initial_Satisfied) | P1: np.mean(Ratio_Solved_Red) | Q1: np.mean(Ratio_Solved_Red_Satisfied) | R1: np.mean(Ratio_Solved_Tse) | S1: np.mean(Ratio_Solved_Tse_Satisfied) | T1: np.mean(Ratio_Solved_After) | U1: np.mean(Ratio_Solved_After_Satisfied) | V1: MAE_Energy | W1: Ratio of global minimum solutions | X1: Ratio of local minimum solutions | Y1: np.mean(Similarity_list_J_Initial) | Z1: np.std(Similarity_list_J_Initial) | AA1: np.mean(Similarity_list_H_Initial) | AB1: np.std(Similarity_list_H_Initial) | AC1: np.mean(Similarity_list_J_Red) | AD1: np.std(Similarity_list_J_Red) | AE1: np.mean(Similarity_list_H_Red) | AF1: np.std(Similarity_list_H_Red) | AG1: np.mean(Similarity_list_J_Tse) | AH1: np.std(Similarity_list_J_Tse) | AI1: np.mean(Similarity_list_H_Tse) | AJ1: np.std(Similarity_list_H_Tse) | AK1: np.mean(Similarity_list_J_After) | AL1: np.std(Similarity_list_J_After) | AM1: np.mean(Similarity_list_H_After) | AN1: np.std(Similarity_list_H_After)
A2: 6 | B2: 0.25666667 | C2: 0.32916675 | D2: 11.069444 | E2: 0.35290068 | F2: 0.44232257 | G2: 15.17701 | H2: 0 | I2: 0 | J2: 0 | K2: 0 | L2: 1 | M2: 1 | N2: 1 | O2: 1 | P2: 1 | Q2: 1 | R2: 1 | S2: 1 | T2: 1 | U2: 1 | V2: 0 | W2: 1 | X2: 0 | Y2: 0.38704157 | Z2: 0.12098157 | AA2: 0.076442796 | AB2: 0.032439107 | AC2: 0.39327667 | AD2: 0.14214055 | AE2: 0.069653469 | AF2: 0.014754916 | AG2: 0.40092552 | AH2: 0.12071435 | AI2: 0.07066764 | AJ2: 0.036036091 | AK2: 0.40716062 | AL2: 0.14130186 | AM2: 0.058600564 | AN2: 0.023476037
A3: 12 | B3: 0.58821762 | C3: 0.74346675 | D3: 12.776773 | E3: 0.56794564 | F3: 0.71002304 | G3: 12.112733 | H3: 0 | I3: 0 | J3: 0 | K3: 0 | L3: 1 | M3: 1 | N3: 0.98255556 | O3: 1 | P3: 0.98111111 | Q3: 1 | R3: 0.98255556 | S3: 1 | T3: 0.98111111 | U3: 1 | V3: 0 | W3: 1 | X3: 0 | Y3: 0.37624554 | Z3: 0.071300449 | AA3: 0.073714187 | AB3: 0.023433117 | AC3: 0.37724359 | AD3: 0.077168809 | AE3: 0.079703505 | AF3: 0.021288204 | AG3: 0.40141418 | AH3: 0.068134307 | AI3: 0.0663664 | AJ3: 0.026494654 | AK3: 0.40305595 | AL3: 0.075167285 | AM3: 0.066396324 | AN3: 0.027683505
A4: 18 | B4: 0.86107126 | C4: 1.0574283 | D4: 12.887832 | E4: 0.78461376 | F4: 0.9503468 | G4: 11.328878 | H4: 0 | I4: 0 | J4: 0 | K4: 0 | L4: 1 | M4: 1 | N4: 0.97007665 | O4: 1 | P4: 0.96637374 | Q4: 1 | R4: 0.97365864 | S4: 1 | T4: 0.97031961 | U4: 1 | V4: 0 | W4: 1 | X4: 0 | Y4: 0.39554536 | Z4: 0.055750985 | AA4: 0.085119618 | AB4: 0.028191392 | AC4: 0.39742582 | AD4: 0.063673881 | AE4: 0.089272546 | AF4: 0.03042015 | AG4: 0.41622673 | AH4: 0.053475981 | AI4: 0.080143479 | AJ4: 0.033161014 | AK4: 0.42033499 | AL4: 0.060732364 | AM4: 0.079723634 | AN4: 0.037708465
A5: 24 | B5: 1.3715089 | C5: 1.6416941 | D5: 15.190105 | E5: 0.8900199 | F5: 1.0301592 | G5: 9.1107479 | H5: 0 | I5: 0 | J5: 0 | K5: 0 | L5: 1 | M5: 1 | N5: 0.96334407 | O5: 1 | P5: 0.95814184 | Q5: 1 | R5: 0.96832021 | S5: 1 | T5: 0.96393879 | U5: 1 | V5: 0 | W5: 1 | X5: 0 | Y5: 0.3855835 | Z5: 0.046102557 | AA5: 0.081050851 | AB5: 0.025078136 | AC5: 0.38379067 | AD5: 0.046909802 | AE5: 0.092099024 | AF5: 0.02075456 | AG5: 0.41718547 | AH5: 0.037984016 | AI5: 0.076796071 | AJ5: 0.030549834 | AK5: 0.4191937 | AL5: 0.038066258 | AM5: 0.082004004 | AN5: 0.031526892
A6: 30 | B6: 1.8012147 | C6: 2.1087958 | D6: 16.244733 | E6: 0.95940621 | F6: 1.0807028 | G6: 7.7693732 | H6: 0 | I6: 0 | J6: 0 | K6: 0 | L6: 1 | M6: 1 | N6: 0.96388762 | O6: 1 | P6: 0.9600288 | Q6: 1 | R6: 0.96911181 | S6: 1 | T6: 0.96591239 | U6: 1 | V6: 0 | W6: 1 | X6: 0 | Y6: 0.37984666 | Z6: 0.045034089 | AA6: 0.083233815 | AB6: 0.023030175 | AC6: 0.37833596 | AD6: 0.050160941 | AE6: 0.091925488 | AF6: 0.024521292 | AG6: 0.41350291 | AH6: 0.041067617 | AI6: 0.079703425 | AJ6: 0.029335265 | AK6: 0.41806018 | AL6: 0.043282275 | AM6: 0.083801804 | AN6: 0.03288976
A7: 36 | B7: 2.1733688 | C7: 2.5295067 | D7: 16.612609 | E7: 1.0574401 | F7: 1.165388 | G7: 6.8387538 | H7: 0.02 | I7: 0.14 | J7: 0.0443 | K7: 0.24194526 | L7: 0.9638 | M7: 0.99685487 | N7: 0.96108994 | O7: 0.99644665 | P7: 0.957399 | Q7: 0.99737489 | R7: 0.96862275 | S7: 0.99672647 | T7: 0.96627319 | U7: 0.99767293 | V7: 0.064240848 | W7: 0.93 | X7: 0.07 | Y7: 0.38678039 | Z7: 0.041948309 | AA7: 0.081971384 | AB7: 0.020949936 | AC7: 0.38710336 | AD7: 0.043493825 | AE7: 0.094297203 | AF7: 0.021726953 | AG7: 0.42631237 | AH7: 0.034661737 | AI7: 0.082511408 | AJ7: 0.029204459 | AK7: 0.43116735 | AL7: 0.035271453 | AM7: 0.090711778 | AN7: 0.035226593
A8: 42 | B8: 2.5080932 | C8: 2.8441965 | D8: 16.396829 | E8: 1.241009 | F8: 1.3363743 | G8: 7.2315821 | H8: 0 | I8: 0 | J8: 0.0057 | K8: 0.075282867 | L8: 0.9943 | M8: 0.9997 | N8: 0.95539402 | O8: 0.99979643 | P8: 0.95044068 | Q8: 0.99979643 | R8: 0.96357173 | S8: 0.99979643 | T8: 0.95996395 | U8: 0.99979643 | V8: 0.039392756 | W8: 0.93 | X8: 0.07 | Y8: 0.38447374 | Z8: 0.03238662 | AA8: 0.083545893 | AB8: 0.019645514 | AC8: 0.38414212 | AD8: 0.036781786 | AE8: 0.096353528 | AF8: 0.019065759 | AG8: 0.41732732 | AH8: 0.031828138 | AI8: 0.079824633 | AJ8: 0.026216523 | AK8: 0.42100142 | AL8: 0.036088409 | AM8: 0.086952401 | AN8: 0.028966317
A9: 48 | B9: 3.0363999 | C9: 3.3976224 | D9: 17.393533 | E9: 1.1879314 | F9: 1.215115 | G9: 5.460472 | H9: 0.08 | I9: 0.30594117 | J9: 0.1004 | K9: 0.33603547 | L9: 0.9109 | M9: 0.99474039 | N9: 0.95601216 | O9: 0.99547028 | P9: 0.95130737 | Q9: 0.99542161 | R9: 0.96500055 | S9: 0.99590647 | T9: 0.96188611 | U9: 0.99591907 | V9: 0.20912469 | W9: 0.75 | X9: 0.25 | Y9: 0.38618134 | Z9: 0.042898391 | AA9: 0.084255472 | AB9: 0.021490806 | AC9: 0.38413558 | AD9: 0.045373191 | AE9: 0.094881958 | AF9: 0.023340961 | AG9: 0.42501694 | AH9: 0.033649286 | AI9: 0.08387019 | AJ9: 0.028849768 | AK9: 0.42875557 | AL9: 0.03345895 | AM9: 0.090361944 | AN9: 0.034475625
A10: 54 | B10: 3.4077348 | C10: 3.8210037 | D10: 17.31816 | E10: 1.2311183 | F10: 1.2426778 | G10: 4.9297114 | H10: 0.04 | I10: 0.19595918 | J10: 0.0553 | K10: 0.24050345 | L10: 0.9475 | M10: 0.99742343 | N10: 0.95803304 | O10: 0.9977354 | P10: 0.95379367 | Q10: 0.9978114 | R10: 0.96568013 | S10: 0.99800302 | T10: 0.96276886 | U10: 0.9980948 | V10: 0.1155347 | W10: 0.76 | X10: 0.24 | Y10: 0.38472422 | Z10: 0.032332864 | AA10: 0.081601769 | AB10: 0.019237191 | AC10: 0.38597573 | AD10: 0.036753765 | AE10: 0.093241259 | AF10: 0.023167696 | AG10: 0.41688716 | AH10: 0.03058059 | AI10: 0.0769611 | AJ10: 0.025472849 | AK10: 0.42303822 | AL10: 0.032885147 | AM10: 0.083126059 | AN10: 0.03072096
A11: 60 | B11: 3.7554391 | C11: 4.13737 | D11: 17.340092 | E11: 1.4378736 | F11: 1.4599752 | G11: 5.2095691 | H11: 0.12 | I11: 0.38157568 | J11: 0.1545 | K11: 0.44858639 | L11: 0.8754 | M11: 0.99345489 | N11: 0.94811546 | O11: 0.99423422 | P11: 0.94305966 | Q11: 0.99485881 | R11: 0.95771408 | S11: 0.99483129 | T11: 0.95432997 | U11: 0.99538106 | V11: 0.30287567 | W11: 0.62 | X11: 0.38 | Y11: 0.38262292 | Z11: 0.02919212 | AA11: 0.086793004 | AB11: 0.02064127 | AC11: 0.37945899 | AD11: 0.031144517 | AE11: 0.099642622 | AF11: 0.023889185 | AG11: 0.41855873 | AH11: 0.031717486 | AI11: 0.085544489 | AJ11: 0.029527133 | AK11: 0.42130055 | AL11: 0.033641124 | AM11: 0.093966114 | AN11: 0.035779433
A12: 66 | B12: 4.3101184 | C12: 4.6951448 | D12: 17.895785 | E12: 1.5712205 | F12: 1.6160496 | G12: 5.3790433 | H12: 0.16 | I12: 0.39293765 | J12: 0.2689 | K12: 0.53869545 | L12: 0.7706 | M12: 0.98949807 | N12: 0.94841557 | O12: 0.99142184 | P12: 0.94251839 | Q12: 0.9915663 | R12: 0.9575689 | S12: 0.99256808 | T12: 0.95368208 | U12: 0.99284583 | V12: 0.35671085 | W12: 0.5355 | X12: 0.4645 | Y12: 0.38495593 | Z12: 0.030203291 | AA12: 0.084561975 | AB12: 0.02262924 | AC12: 0.38377264 | AD12: 0.032709193 | AE12: 0.096170708 | AF12: 0.022039386 | AG12: 0.42258709 | AH12: 0.032681272 | AI12: 0.084324694 | AJ12: 0.02943014 | AK12: 0.42689078 | AL12: 0.03412474 | AM12: 0.091818987 | AN12: 0.033298969
A13: 72 | B13: 4.6348768 | C13: 5.0279489 | D13: 17.813619 | E13: 1.6009538 | F13: 1.6245055 | G13: 4.9313866 | H13: 0.15 | I13: 0.38405729 | J13: 0.2718 | K13: 0.50963198 | L13: 0.7591 | M13: 0.98975414 | N13: 0.94344152 | O13: 0.99065481 | P13: 0.93782209 | Q13: 0.99203703 | R13: 0.95484636 | S13: 0.99220703 | T13: 0.95107663 | U13: 0.99346707 | V13: 0.57212877 | W13: 0.47 | X13: 0.53 | Y13: 0.38707677 | Z13: 0.033738849 | AA13: 0.085737845 | AB13: 0.022029323 | AC13: 0.38676576 | AD13: 0.037997397 | AE13: 0.096637839 | AF13: 0.023304137 | AG13: 0.42112978 | AH13: 0.030888339 | AI13: 0.083420311 | AJ13: 0.030942538 | AK13: 0.42537501 | AL13: 0.034380941 | AM13: 0.089707185 | AN13: 0.037203926
... A21: 120 | B21: 7.6764183 | C21: 8.0939366 | D21: 17.856378 | E21: 2.4814217 | F21: 2.5174834 | G21: 4.2322422 | H21: 0.49 | I21: 0.72794231 | J21: 0.7673 | K21: 0.91178435 | L21: 0.4798 | M21: 0.9825521 | N21: 0.93236442 | O21: 0.98532635 | P21: 0.92738504 | Q21: 0.98616432 | R21: 0.94755818 | S21: 0.9883367 | T21: 0.94448086 | U21: 0.98917477 | V21: 1.5879896 | W21: 0.09 | X21: 0.91 | Y21: 0.38559672 | Z21: 0.034545773 | AA21: 0.087560148 | AB21: 0.020360034 | AC21: 0.384781 | AD21: 0.036311343 | AE21: 0.10221735 | AF21: 0.024581012 | AG21: 0.42581047 | AH21: 0.031543292 | AI21: 0.087642722 | AJ21: 0.026382141 | AK21: 0.42961005 | AL21: 0.03203391 | AM21: 0.097409962 | AN21: 0.033659473

Sheet Case-3
A1: N | B1: MAE_Learn | C1: RMSE_Learn | D1: MAPE_Learn | E1: Standard_MAE_Learn | F1: Standard_RMSE_Learn | G1: Standard_MAPE_Learn | H1: np.mean(Z_SATSolver_index_list) | I1: np.std(Z_SATSolver_index_list) | J1: np.mean(Num_Solved_SAT) | K1: np.std(Num_Solved_SAT) | L1: Solved_SAT_Count / (Maxcomb * NumTrail) | M1: np.mean(Ratio_Solved_Component) | N1: np.mean(Ratio_Solved_Initial) | O1: np.mean(Ratio_Solved_Initial_Satisfied) | P1: np.mean(Ratio_Solved_Red) | Q1: np.mean(Ratio_Solved_Red_Satisfied) | R1: np.mean(Ratio_Solved_Tse) | S1: np.mean(Ratio_Solved_Tse_Satisfied) | T1: np.mean(Ratio_Solved_After) | U1: np.mean(Ratio_Solved_After_Satisfied) | V1: MAE_Energy | W1: Ratio of global minimum solutions | X1: Ratio of local minimum solutions | Y1: np.mean(Similarity_list_J_Initial) | Z1: np.std(Similarity_list_J_Initial) | AA1: np.mean(Similarity_list_H_Initial) | AB1: np.std(Similarity_list_H_Initial) | AC1: np.mean(Similarity_list_J_Red) | AD1: np.std(Similarity_list_J_Red) | AE1: np.mean(Similarity_list_H_Red) | AF1: np.std(Similarity_list_H_Red) | AG1: np.mean(Similarity_list_J_Tse) | AH1: np.std(Similarity_list_J_Tse) | AI1: np.mean(Similarity_list_H_Tse) | AJ1: np.std(Similarity_list_H_Tse) | AK1: np.mean(Similarity_list_J_After) | AL1: np.std(Similarity_list_J_After) | AM1: np.mean(Similarity_list_H_After) | AN1: np.std(Similarity_list_H_After)
A2: 6 | B2: 0.3085 | C2: 0.40080727 | D2: 14.147222 | E2: 0.37922066 | F2: 0.48599061 | G2: 17.27837 | H2: 0 | I2: 0 | J2: 0 | K2: 0 | L2: 1 | M2: 1 | N2: 0.93228571 | O2: 1 | P2: 0.92966667 | Q2: 1 | R2: 0.93228571 | S2: 1 | T2: 0.92966667 | U2: 1 | V2: 0 | W2: 1 | X2: 0 | Y2: 0.37680518 | Z2: 0.095586713 | AA2: 0.17438436 | AB2: 0.15718829 | AC2: 0.37456876 | AD2: 0.10639959 | AE2: 0.17993496 | AF2: 0.1583505 | AG2: 0.38262576 | AH2: 0.094440651 | AI2: 0.16374948 | AJ2: 0.1610185 | AK2: 0.38038933 | AL2: 0.10549467 | AM2: 0.162354 | AN2: 0.16310519
A3: 12 | B3: 0.62129315 | C3: 0.78084146 | D3: 14.181978 | E3: 0.56216305 | F3: 0.69131018 | G3: 12.487023 | H3: 0 | I3: 0 | J3: 0 | K3: 0 | L3: 1 | M3: 1 | N3: 0.88433081 | O3: 1 | P3: 0.87402778 | Q3: 1 | R3: 0.89265152 | S3: 1 | T3: 0.88323232 | U3: 1 | V3: 0 | W3: 1 | X3: 0 | Y3: 0.34729996 | Z3: 0.04838825 | AA3: 0.12943646 | AB3: 0.024458211 | AC3: 0.34278296 | AD3: 0.04711264 | AE3: 0.15163753 | AF3: 0.019801906 | AG3: 0.36291615 | AH3: 0.046043627 | AI3: 0.11116741 | AJ3: 0.030767468 | AK3: 0.35966733 | AL3: 0.045965383 | AM3: 0.12097023 | AN3: 0.025078533
A4: 18 | B4: 0.94238849 | C4: 1.1542188 | D4: 14.683622 | E4: 0.77749756 | F4: 0.92404376 | G4: 11.380001 | H4: 0 | I4: 0 | J4: 0 | K4: 0 | L4: 1 | M4: 1 | N4: 0.87206527 | O4: 1 | P4: 0.86370696 | Q4: 1 | R4: 0.88831008 | S4: 1 | T4: 0.88089593 | U4: 1 | V4: 0 | W4: 1 | X4: 0 | Y4: 0.35926084 | Z4: 0.034603415 | AA4: 0.14244985 | AB4: 0.026813111 | AC4: 0.35450354 | AD4: 0.031339607 | AE4: 0.17197964 | AF4: 0.021949382 | AG4: 0.38147183 | AH4: 0.04218055 | AI4: 0.13210447 | AJ4: 0.040349552 | AK4: 0.3782138 | AL4: 0.041410578 | AM4: 0.15062798 | AN4: 0.045185922
A5: 24 | B5: 1.3197431 | C5: 1.5992017 | D5: 15.447997 | E5: 0.83354079 | F5: 0.98637682 | G5: 9.4494617 | H5: 0 | I5: 0 | J5: 0 | K5: 0 | L5: 1 | M5: 1 | N5: 0.87703802 | O5: 1 | P5: 0.86682885 | Q5: 1 | R5: 0.88903038 | S5: 1 | T5: 0.87977124 | U5: 1 | V5: 0 | W5: 1 | X5: 0 | Y5: 0.36133168 | Z5: 0.033052655 | AA5: 0.1401385 | AB5: 0.028869746 | AC5: 0.35582607 | AD5: 0.030221708 | AE5: 0.16517318 | AF5: 0.023769055 | AG5: 0.37931078 | AH5: 0.035138854 | AI5: 0.12451521 | AJ5: 0.03569892 | AK5: 0.37541399 | AL5: 0.033965056 | AM5: 0.13773459 | AN5: 0.033503368
A6: 30 | B6: 1.639414 | C6: 1.9516946 | D6: 15.735984 | E6: 0.8845288 | F6: 1.0063646 | G6: 8.0053039 | H6: 0 | I6: 0 | J6: 0 | K6: 0 | L6: 1 | M6: 1 | N6: 0.87846943 | O6: 1 | P6: 0.86828815 | Q6: 1 | R6: 0.89481815 | S6: 1 | T6: 0.88636392 | U6: 1 | V6: 0 | W6: 1 | X6: 0 | Y6: 0.3591389 | Z6: 0.029007613 | AA6: 0.1405197 | AB6: 0.02312828 | AC6: 0.35350035 | AD6: 0.026642323 | AE6: 0.16638492 | AF6: 0.024284307 | AG6: 0.38557242 | AH6: 0.032282455 | AI6: 0.12861125 | AJ6: 0.028533816 | AK6: 0.38251934 | AL6: 0.033441585 | AM6: 0.14404919 | AN6: 0.031937547
A7: 36 | B7: 2.3169567 | C7: 2.6460162 | D7: 18.028704 | E7: 0.97558932 | F7: 1.0630668 | G7: 6.860448 | H7: 0.01 | I7: 0.099498744 | J7: 0.01 | K7: 0.099498744 | L7: 0.99 | M7: 0.99933333 | N7: 0.8727704 | O7: 0.99965517 | P7: 0.86518278 | Q7: 0.99962963 | R7: 0.88749287 | S7: 0.99965517 | T7: 0.88115132 | U7: 0.99962963 | V7: 0.016245106 | W7: 0.98 | X7: 0.02 | Y7: 0.35625888 | Z7: 0.023525925 | AA7: 0.13607479 | AB7: 0.020568622 | AC7: 0.35213522 | AD7: 0.022109764 | AE7: 0.16728954 | AF7: 0.02099571 | AG7: 0.37977021 | AH7: 0.027908319 | AI7: 0.12046219 | AJ7: 0.029911215 | AK7: 0.3775494 | AL7: 0.028701116 | AM7: 0.13875239 | AN7: 0.03386395
A8: 42 | B8: 2.6054957 | C8: 2.9838235 | D8: 17.764577 | E8: 0.99919263 | F8: 1.0870507 | G8: 5.9204135 | H8: 0 | I8: 0 | J8: 0.0043 | K8: 0.065433248 | L8: 0.9957 | M8: 0.99969286 | N8: 0.87760935 | O8: 0.99972258 | P8: 0.86796655 | Q8: 0.99985172 | R8: 0.89524191 | S8: 0.999785 | T8: 0.88745641 | U8: 0.99988684 | V8: 0.049686266 | W8: 0.93 | X8: 0.07 | Y8: 0.36131782 | Z8: 0.022348683 | AA8: 0.13862384 | AB8: 0.025782116 | AC8: 0.35617816 | AD8: 0.019147246 | AE8: 0.16537946 | AF8: 0.022446823 | AG8: 0.38814042 | AH8: 0.024809631 | AI8: 0.12847513 | AJ8: 0.034859819 | AK8: 0.38558589 | AL8: 0.025660844 | AM8: 0.14499444 | AN8: 0.036562013
A9: 48 | B9: 3.1064717 | C9: 3.4865104 | D9: 18.475494 | E9: 1.0390126 | F9: 1.0933569 | G9: 5.3237514 | H9: 0.04 | I9: 0.19595918 | J9: 0.054 | K9: 0.23808402 | L9: 0.9488 | M9: 0.99701176 | N9: 0.87655209 | O9: 0.99824653 | P9: 0.86712296 | Q9: 0.99834799 | R9: 0.89406678 | S9: 0.9984342 | T9: 0.88701707 | U9: 0.99854754 | V9: 0.17560694 | W9: 0.81 | X9: 0.19 | Y9: 0.35856205 | Z9: 0.025655199 | AA9: 0.13780139 | AB9: 0.024416413 | AC9: 0.35359608 | AD9: 0.023013344 | AE9: 0.16472361 | AF9: 0.021730411 | AG9: 0.38631915 | AH9: 0.030309017 | AI9: 0.12694883 | AJ9: 0.030203868 | AK9: 0.38478162 | AL9: 0.030267764 | AM9: 0.14363189 | AN9: 0.030427747
A10: 54 | B10: 3.4859287 | C10: 3.8472056 | D10: 18.280008 | E10: 1.2386891 | F10: 1.3115164 | G10: 5.8564006 | H10: 0.23 | I10: 0.50705029 | J10: 0.2756 | K10: 0.58124405 | L10: 0.7857 | M10: 0.98636682 | N10: 0.86950359 | O10: 0.99194216 | P10: 0.8611556 | Q10: 0.99267451 | R10: 0.88490815 | S10: 0.99261279 | T10: 0.87816195 | U10: 0.99330681 | V10: 0.34494017 | W10: 0.67 | X10: 0.33 | Y10: 0.35909764 | Z10: 0.023207615 | AA10: 0.1376051 | AB10: 0.020031708 | AC10: 0.35528078 | AD10: 0.020209334 | AE10: 0.16508265 | AF10: 0.022967002 | AG10: 0.38511095 | AH10: 0.025132854 | AI10: 0.12442768 | AJ10: 0.027011481 | AK10: 0.38368648 | AL10: 0.025505967 | AM10: 0.14073882 | AN10: 0.031247878
A11: 60 | B11: 3.9994679 | C11: 4.3874095 | D11: 18.983747 | E11: 1.1316229 | F11: 1.1645466 | G11: 4.4173339 | H11: 0.18 | I11: 0.43312816 | J11: 0.2313 | K11: 0.47707474 | L11: 0.7936 | M11: 0.98960403 | N11: 0.8717233 | O11: 0.99373297 | P11: 0.86351874 | Q11: 0.99444212 | R11: 0.8902358 | S11: 0.99436006 | T11: 0.8837674 | U11: 0.99501393 | V11: 0.46265114 | W11: 0.52 | X11: 0.48 | Y11: 0.36062154 | Z11: 0.022495082 | AA11: 0.13646968 | AB11: 0.025119925 | AC11: 0.3555726 | AD11: 0.020138551 | AE11: 0.1640175 | AF11: 0.024972367 | AG11: 0.39084313 | AH11: 0.023920878 | AI11: 0.12641065 | AJ11: 0.031151214 | AK11: 0.38881055 | AL11: 0.02422563 | AM11: 0.14372332 | AN11: 0.034899157
A12: 66 | B12: 4.3889418 | C12: 4.7781919 | D12: 18.947038 | E12: 1.2682896 | F12: 1.2994726 | G12: 4.7830242 | H12: 0.35 | I12: 0.62249498 | J12: 0.4558 | K12: 0.73146863 | L12: 0.6641 | M12: 0.98060391 | N12: 0.86824178 | O12: 0.98906164 | P12: 0.85889753 | Q12: 0.98948315 | R12: 0.8858258 | S12: 0.99005267 | T12: 0.87847939 | U12: 0.99048548 | V12: 0.66755371 | W12: 0.39 | X12: 0.61 | Y12: 0.36195511 | Z12: 0.020626595 | AA12: 0.13743059 | AB12: 0.022024674 | AC12: 0.35657006 | AD12: 0.018368306 | AE12: 0.16521921 | AF12: 0.022318824 | AG12: 0.39206986 | AH12: 0.024553292 | AI12: 0.12817686 | AJ12: 0.030010383 | AK12: 0.38978308 | AL12: 0.025335494 | AM12: 0.14597181 | AN12: 0.034353403
A13: 72 | B13: 5.0541741 | C13: 5.4537793 | D13: 19.987514 | E13: 1.2995145 | F13: 1.3298042 | G13: 3.9483421 | H13: 0.28 | I13: 0.53065997 | J13: 0.3605 | K13: 0.61313926 | L13: 0.7045 | M13: 0.98594821 | N13: 0.86808387 | O13: 0.9918534 | P13: 0.85963374 | Q13: 0.99266754 | R13: 0.88495289 | S13: 0.99237757 | T13: 0.87850557 | U13: 0.99322147 | V13: 0.78759339 | W13: 0.42 | X13: 0.58 | Y13: 0.35797229 | Z13: 0.021790114 | AA13: 0.1366919 | AB13: 0.022512536 | AC13: 0.35441798 | AD13: 0.019963844 | AE13: 0.16506568 | AF13: 0.024079484 | AG13: 0.38916337 | AH13: 0.023403377 | AI13: 0.12667722 | AJ13: 0.030303757 | AK13: 0.38885856 | AL13: 0.023130773 | AM13: 0.14469762 | AN13: 0.03493553
... A21: 120 | B21: 8.2717821 | C21: 8.692407 | D21: 19.718171 | E21: 1.9617951 | F21: 1.9691251 | G21: 3.4414905 | H21: 0.86 | I21: 0.98 | J21: 1.0882 | K21: 1.099191 | L21: 0.3579 | M21: 0.97404589 | N21: 0.8641626 | O21: 0.98449341 | P21: 0.856393 | Q21: 0.98579756 | R21: 0.88133526 | S21: 0.98633055 | T21: 0.87531022 | U21: 0.98763352 | V21: 2.0405439 | W21: 0.03 | X21: 0.97 | Y21: 0.36341888 | Z21: 0.016491805 | AA21: 0.13362076 | AB21: 0.02014417 | AC21: 0.35797548 | AD21: 0.01557488 | AE21: 0.16234813 | AF21: 0.020417048 | AG21: 0.38810485 | AH21: 0.019732296 | AI21: 0.11947517 | AJ21: 0.025934846 | AK21: 0.38540882 | AL21: 0.020322076 | AM21: 0.13630849 | AN21: 0.028581678

Sheet Case-4
A1: N | B1: MAE_Learn | C1: RMSE_Learn | D1: MAPE_Learn | E1: Standard_MAE_Learn | F1: Standard_RMSE_Learn | G1: Standard_MAPE_Learn | H1: np.mean(Z_SATSolver_index_list) | I1: np.std(Z_SATSolver_index_list) | J1: np.mean(Num_Solved_SAT) | K1: np.std(Num_Solved_SAT) | L1: Solved_SAT_Count / (Maxcomb * NumTrail) | M1: np.mean(Ratio_Solved_Component) | N1: np.mean(Ratio_Solved_Initial) | O1: np.mean(Ratio_Solved_Initial_Satisfied) | P1: np.mean(Ratio_Solved_Red) | Q1: np.mean(Ratio_Solved_Red_Satisfied) | R1: np.mean(Ratio_Solved_Tse) | S1: np.mean(Ratio_Solved_Tse_Satisfied) | T1: np.mean(Ratio_Solved_After) | U1: np.mean(Ratio_Solved_After_Satisfied) | V1: MAE_Energy | W1: Ratio of global minimum solutions | X1: Ratio of local minimum solutions | Y1: np.mean(Similarity_list_J_Initial) | Z1: np.std(Similarity_list_J_Initial) | AA1: np.mean(Similarity_list_H_Initial) | AB1: np.std(Similarity_list_H_Initial) | AC1: np.mean(Similarity_list_J_Red) | AD1: np.std(Similarity_list_J_Red) | AE1: np.mean(Similarity_list_H_Red) | AF1: np.std(Similarity_list_H_Red) | AG1: np.mean(Similarity_list_J_Tse) | AH1: np.std(Similarity_list_J_Tse) | AI1: np.mean(Similarity_list_H_Tse) | AJ1: np.std(Similarity_list_H_Tse) | AK1: np.mean(Similarity_list_J_After) | AL1: np.std(Similarity_list_J_After) | AM1: np.mean(Similarity_list_H_After) | AN1: np.std(Similarity_list_H_After)
A2: 6 | B2: 0.27816667 | C2: 0.36029735 | D2: 13.908333 | E2: 0.36545022 | F2: 0.47154266 | G2: 18.272511 | H2: 0 | I2: 0 | J2: 0 | K2: 0 | L2: 1 | M2: 1 | N2: 0.84547619 | O2: 1 | P2: 0.83333333 | Q2: 1 | R2: 0.84547619 | S2: 1 | T2: 0.83333333 | U2: 1 | V2: 0 | W2: 1 | X2: 0 | Y2: 0.32873009 | Z2: 0.050051111 | AA2: 0.22247515 | AB2: 0.028756116 | AC2: 0.31829051 | AD2: 0.040823569 | AE2: 0.24891656 | AF2: 0.0060259639 | AG2: 0.32873009 | AH2: 0.050051111 | AI2: 0.20045612 | AJ2: 0.051172148 | AK2: 0.31829051 | AL2: 0.040823569 | AM2: 0.21553514 | AN2: 0.037935184
A3: 12 | B3: 0.62156396 | C3: 0.78268347 | D3: 14.405545 | E3: 0.56525311 | F3: 0.69806452 | G3: 12.830707 | H3: 0 | I3: 0 | J3: 0 | K3: 0 | L3: 1 | M3: 1 | N3: 0.84435897 | O3: 1 | P3: 0.83653846 | Q3: 1 | R3: 0.84802564 | S3: 1 | T3: 0.84020513 | U3: 1 | V3: 0 | W3: 1 | X3: 0 | Y3: 0.3347396 | Z3: 0.032234268 | AA3: 0.19817008 | AB3: 0.038032693 | AC3: 0.32878076 | AD3: 0.028782883 | AE3: 0.23373288 | AF3: 0.026511072 | AG3: 0.34051347 | AH3: 0.033755511 | AI3: 0.17201903 | AJ3: 0.050660244 | AK3: 0.33455463 | AL3: 0.031585629 | AM3: 0.19285449 | AN3: 0.044770337
A4: 18 | B4: 1.0331965 | C4: 1.2823091 | D4: 16.282187 | E4: 0.65004549 | F4: 0.77722635 | G4: 9.9450228 | H4: 0 | I4: 0 | J4: 0 | K4: 0 | L4: 1 | M4: 1 | N4: 0.84241737 | O4: 1 | P4: 0.83552514 | Q4: 1 | R4: 0.85306304 | S4: 1 | T4: 0.84644422 | U4: 1 | V4: 0 | W4: 1 | X4: 0 | Y4: 0.33895835 | Z4: 0.026319715 | AA4: 0.19986645 | AB4: 0.028260837 | AC4: 0.33527465 | AD4: 0.023214576 | AE4: 0.23718846 | AF4: 0.018705378 | AG4: 0.35285678 | AH4: 0.033029689 | AI4: 0.17853752 | AJ4: 0.039537267 | AK4: 0.34966188 | AL4: 0.031449203 | AM4: 0.20235046 | AN4: 0.036600903
A5: 24 | B5: 1.2684104 | C5: 1.5276988 | D5: 15.40788 | E5: 0.78102282 | F5: 0.92069526 | G5: 9.2079677 | H5: 0 | I5: 0 | J5: 0 | K5: 0 | L5: 1 | M5: 1 | N5: 0.84067995 | O5: 1 | P5: 0.83458487 | Q5: 1 | R5: 0.85490128 | S5: 1 | T5: 0.84929989 | U5: 1 | V5: 0 | W5: 1 | X5: 0 | Y5: 0.34135735 | Z5: 0.024008179 | AA5: 0.2024709 | AB5: 0.024244034 | AC5: 0.33749784 | AD5: 0.021005843 | AE5: 0.24242722 | AF5: 0.019860758 | AG5: 0.36059317 | AH5: 0.030560738 | AI5: 0.1843128 | AJ5: 0.038901365 | AK5: 0.3573741 | AL5: 0.030536927 | AM5: 0.2114738 | AN5: 0.042236414
A6: 30 | B6: 1.7322188 | C6: 2.0421041 | D6: 16.942178 | E6: 0.85189799 | F6: 0.96362466 | G6: 8.0149512 | H6: 0 | I6: 0 | J6: 0 | K6: 0 | L6: 1 | M6: 1 | N6: 0.84366233 | O6: 1 | P6: 0.83564619 | Q6: 1 | R6: 0.85681168 | S6: 1 | T6: 0.84934286 | U6: 1 | V6: 0 | W6: 1 | X6: 0 | Y6: 0.34810806 | Z6: 0.022131549 | AA6: 0.20584582 | AB6: 0.03261641 | AC6: 0.34335641 | AD6: 0.019630862 | AE6: 0.24146699 | AF6: 0.030472155 | AG6: 0.36573058 | AH6: 0.02473628 | AI6: 0.18776305 | AJ6: 0.038575682 | AK6: 0.36178849 | AL6: 0.02494334 | AM6: 0.21157409 | AN6: 0.039052918
A7: 36 | B7: 2.3534804 | C7: 2.6850795 | D7: 19.044373 | E7: 0.87436009 | F7: 0.9669078 | G7: 6.7438221 | H7: 0 | I7: 0 | J7: 0 | K7: 0 | L7: 1 | M7: 1 | N7: 0.84375107 | O7: 1 | P7: 0.83568263 | Q7: 1 | R7: 0.85351201 | S7: 1 | T7: 0.84616562 | U7: 1 | V7: 0 | W7: 1 | X7: 0 | Y7: 0.3469179 | Z7: 0.019669026 | AA7: 0.20330398 | AB7: 0.028380806 | AC7: 0.34243118 | AD7: 0.016746028 | AE7: 0.23912049 | AF7: 0.026164345 | AG7: 0.35977952 | AH7: 0.02351229 | AI7: 0.18036175 | AJ7: 0.035473609 | AK7: 0.3564304 | AL7: 0.022407249 | AM7: 0.20314046 | AN7: 0.034778183
A8: 42 | B8: 2.8380855 | C8: 3.2008317 | D8: 19.478409 | E8: 0.90616403 | F8: 0.95466039 | G8: 5.5995838 | H8: 0.03 | I8: 0.17058722 | J8: 0.0427 | K8: 0.22688479 | L8: 0.9626 | M8: 0.99720143 | N8: 0.83972319 | O8: 0.99843405 | P8: 0.83476958 | Q8: 0.99889626 | R8: 0.85231264 | S8: 0.99843405 | T8: 0.84794499 | U8: 0.99889626 | V8: 0.099939186 | W8: 0.91 | X8: 0.09 | Y8: 0.34481691 | Z8: 0.01627801 | AA8: 0.19702914 | AB8: 0.02898417 | AC8: 0.34182717 | AD8: 0.013644722 | AE8: 0.2382098 | AF8: 0.026587967 | AG8: 0.36250135 | AH8: 0.021670149 | AI8: 0.17448386 | AJ8: 0.03726266 | AK8: 0.36031921 | AL8: 0.021839411 | AM8: 0.20120642 | AN8: 0.0387034
A9: 48 | B9: 3.2964915 | C9: 3.6894033 | D9: 19.92749 | E9: 0.98049046 | F9: 1.041401 | G9: 5.3005893 | H9: 0.06 | I9: 0.2764055 | J9: 0.0673 | K9: 0.28769899 | L9: 0.9427 | M9: 0.99596936 | N9: 0.8412124 | O9: 0.9983969 | P9: 0.83479792 | Q9: 0.99833833 | R9: 0.85517949 | S9: 0.99853925 | T9: 0.84957314 | U9: 0.99849497 | V9: 0.21010512 | W9: 0.81 | X9: 0.19 | Y9: 0.3466117 | Z9: 0.013952393 | AA9: 0.19765054 | AB9: 0.026968324 | AC9: 0.34315596 | AD9: 0.012818727 | AE9: 0.23691942 | AF9: 0.024576358 | AG9: 0.36553757 | AH9: 0.021547475 | AI9: 0.17685633 | AJ9: 0.032679648 | AK9: 0.36315376 | AL9: 0.022334211 | AM9: 0.20275826 | AN9: 0.033970205
A10: 54 | B10: 3.6649527 | C10: 4.0227496 | D10: 19.618784 | E10: 1.1240353 | F10: 1.2118362 | G10: 5.5639173 | H10: 0.23 | I10: 0.52640289 | J10: 0.2562 | K10: 0.56014423 | L10: 0.8054 | M10: 0.98674354 | N10: 0.83668474 | O10: 0.99436333 | P10: 0.83132236 | Q10: 0.99468847 | R10: 0.85104669 | S10: 0.9947586 | T10: 0.84636184 | U10: 0.99506798 | V10: 0.41280008 | W10: 0.6 | X10: 0.4 | Y10: 0.34754705 | Z10: 0.013565103 | AA10: 0.1965225 | AB10: 0.025440619 | AC10: 0.34446077 | AD10: 0.011296641 | AE10: 0.23696137 | AF10: 0.023719725 | AG10: 0.36749562 | AH10: 0.018270136 | AI10: 0.17624934 | AJ10: 0.03231951 | AK10: 0.36538746 | AL10: 0.018828252 | AM10: 0.20300519 | AN10: 0.033564476
A11: 60 | B11: 4.1555084 | C11: 4.5479495 | D11: 20.353111 | E11: 0.8683456 | F11: 0.87618034 | G11: 3.5023676 | H11: 0.16 | I11: 0.44090815 | J11: 0.1742 | K11: 0.4624439 | L11: 0.8583 | M11: 0.9916895 | N11: 0.83862841 | O11: 0.99651404 | P11: 0.83253546 | Q11: 0.99659286 | R11: 0.85306208 | S11: 0.99678804 | T11: 0.84766748 | U11: 0.99685814 | V11: 0.37890897 | W11: 0.66 | X11: 0.34 | Y11: 0.34778737 | Z11: 0.013963 | AA11: 0.20085276 | AB11: 0.028573388 | AC11: 0.34383972 | AD11: 0.011141475 | AE11: 0.24125914 | AF11: 0.027621036 | AG11: 0.36752149 | AH11: 0.017678855 | AI11: 0.18113164 | AJ11: 0.036337943 | AK11: 0.36464195 | AL11: 0.017664456 | AM11: 0.20817426 | AN11: 0.038767976
A12: 66 | B12: 4.4740291 | C12: 4.8719941 | D12: 19.891695 | E12: 1.0803314 | F12: 1.1076717 | G12: 4.3023488 | H12: 0.6 | I12: 0.83666003 | J12: 0.6355 | K12: 0.86973545 | L12: 0.5575 | M12: 0.97215077 | N12: 0.83402633 | O12: 0.98875325 | P12: 0.82688293 | Q12: 0.98862024 | R12: 0.84851556 | S12: 0.98967806 | T12: 0.84226926 | U12: 0.98956486 | V12: 0.91156989 | W12: 0.37 | X12: 0.63 | Y12: 0.34675058 | Z12: 0.013749193 | AA12: 0.19859253 | AB12: 0.025202976 | AC12: 0.34289341 | AD12: 0.011168758 | AE12: 0.23655045 | AF12: 0.021805113 | AG12: 0.36798331 | AH12: 0.020496265 | AI12: 0.18101032 | AJ12: 0.032580128 | AK12: 0.36571428 | AL12: 0.02015119 | AM12: 0.20666785 | AN12: 0.031641893
A13: 72 | B13: 4.9698128 | C13: 5.3651481 | D13: 20.202574 | E13: 0.99095687 | F13: 1.0170025 | G13: 3.4084413 | H13: 0.62 | I13: 0.77175126 | J13: 0.6681 | K13: 0.83507029 | L13: 0.5331 | M13: 0.973141 | N13: 0.83362165 | O13: 0.98855653 | P13: 0.82659467 | Q13: 0.98889689 | R13: 0.84739597 | S13: 0.98942393 | T13: 0.84133289 | U13: 0.98977694 | V13: 1.0205554 | W13: 0.27 | X13: 0.73 | Y13: 0.34825373 | Z13: 0.01394432 | AA13: 0.20214215 | AB13: 0.021908196 | AC13: 0.34409789 | AD13: 0.011306259 | AE13: 0.23880887 | AF13: 0.020773194 | AG13: 0.36838316 | AH13: 0.019382053 | AI13: 0.18452432 | AJ13: 0.030304357 | AK13: 0.36590814 | AL13: 0.019722497 | AM13: 0.20951127 | AN13: 0.031997582
... A21: 120 | B21: 8.3896201 | C21: 8.7895307 | D21: 20.54136 | E21: 1.4665979 | F21: 1.4893806 | G21: 2.9513936 | H21: 1.06 | I21: 1.0938007 | J21: 1.2534 | K21: 1.1098596 | L21: 0.2728 | M21: 0.96945324 | N21: 0.8304599 | O21: 0.98689768 | P21: 0.82460646 | Q21: 0.98762896 | R21: 0.84603181 | S21: 0.98827626 | T21: 0.84104517 | U21: 0.98896546 | V21: 2.2877194 | W21: 0.02 | X21: 0.98 | Y21: 0.35201037 | Z21: 0.013063323 | AA21: 0.19892776 | AB21: 0.024257669 | AC21: 0.34765779 | AD21: 0.010895361 | AE21: 0.23809361 | AF21: 0.024059558 | AG21: 0.37172703 | AH21: 0.019013021 | AI21: 0.18048146 | AJ21: 0.033371079 | AK21: 0.3686795 | AL21: 0.01950838 | AM21: 0.20709783 | AN21: 0.038029667

Sheet Case-5
A1: N | B1: MAE_Learn | C1: RMSE_Learn | D1: MAPE_Learn | E1: Standard_MAE_Learn | F1: Standard_RMSE_Learn | G1: Standard_MAPE_Learn | H1: np.mean(Z_SATSolver_index_list) | I1: np.std(Z_SATSolver_index_list) | J1: np.mean(Num_Solved_SAT) | K1: np.std(Num_Solved_SAT) | L1: Solved_SAT_Count / (Maxcomb * NumTrail) | M1: np.mean(Ratio_Solved_Component) | N1: np.mean(Ratio_Solved_Initial) | O1: np.mean(Ratio_Solved_Initial_Satisfied) | P1: np.mean(Ratio_Solved_Red) | Q1: np.mean(Ratio_Solved_Red_Satisfied) | R1: np.mean(Ratio_Solved_Tse) | S1: np.mean(Ratio_Solved_Tse_Satisfied) | T1: np.mean(Ratio_Solved_After) | U1: np.mean(Ratio_Solved_After_Satisfied) | V1: MAE_Energy | W1: Ratio of global minimum solutions | X1: Ratio of local minimum solutions | Y1: np.mean(Similarity_list_J_Initial) | Z1: np.std(Similarity_list_J_Initial) | AA1: np.mean(Similarity_list_H_Initial) | AB1: np.std(Similarity_list_H_Initial) | AC1: np.mean(Similarity_list_J_Red) | AD1: np.std(Similarity_list_J_Red) | AE1: np.mean(Similarity_list_H_Red) | AF1: np.std(Similarity_list_H_Red) | AG1: np.mean(Similarity_list_J_Tse) | AH1: np.std(Similarity_list_J_Tse) | AI1: np.mean(Similarity_list_H_Tse) | AJ1: np.std(Similarity_list_H_Tse) | AK1: np.mean(Similarity_list_J_After) | AL1: np.std(Similarity_list_J_After) | AM1: np.mean(Similarity_list_H_After) | AN1: np.std(Similarity_list_H_After)
A2: 6 | B2: 0.3192619 | C2: 0.42356753 | D2: 14.38254 | E2: 0.36225721 | F2: 0.46893504 | G2: 16.100119 | H2: 0 | I2: 0 | J2: 0 | K2: 0 | L2: 1 | M2: 1 | N2: 0.9412381 | O2: 1 | P2: 0.93766667 | Q2: 1 | R2: 0.9412381 | S2: 1 | T2: 0.93766667 | U2: 1 | V2: 0 | W2: 1 | X2: 0 | Y2: 0.38390224 | Z2: 0.099143742 | AA2: 0.14268707 | AB2: 0.12328013 | AC2: 0.38571654 | AD2: 0.1048235 | AE2: 0.15239263 | AF2: 0.12466868 | AG2: 0.39084197 | AH2: 0.092964819 | AI2: 0.13192776 | AJ2: 0.12483205 | AK2: 0.39265627 | AL2: 0.098872441 | AM2: 0.13406645 | AN2: 0.1260255
A3: 12 | B3: 0.65319841 | C3: 0.825408 | D3: 16.32996 | E3: 0.53724301 | F3: 0.66672265 | G3: 13.431075 | H3: 0 | I3: 0 | J3: 0 | K3: 0 | L3: 1 | M3: 1 | N3: 0.81713235 | O3: 1 | P3: 0.8125 | Q3: 1 | R3: 0.81713235 | S3: 1 | T3: 0.8125 | U3: 1 | V3: 0 | W3: 1 | X3: 0 | Y3: 0.33069295 | Z3: 0.020882197 | AA3: 0.32602808 | AB3: 0.020255955 | AC3: 0.32759941 | AD3: 0.016583648 | AE3: 0.36050526 | AF3: 0.0059629605 | AG3: 0.33069295 | AH3: 0.020882197 | AI3: 0.29759441 | AJ3: 0.044410991 | AK3: 0.32759941 | AL3: 0.016583648 | AM3: 0.32364967 | AN3: 0.036905063
A4: 18 | B4: 1.0500885 | C4: 1.2863465 | D4: 17.501474 | E4: 0.61648984 | F4: 0.74039112 | G4: 10.274831 | H4: 0 | I4: 0 | J4: 0 | K4: 0 | L4: 1 | M4: 1 | N4: 0.82401186 | O4: 1 | P4: 0.81818182 | Q4: 1 | R4: 0.83077549 | S4: 1 | T4: 0.82494545 | U4: 1 | V4: 0 | W4: 1 | X4: 0 | Y4: 0.33643049 | Z4: 0.019923945 | AA4: 0.28229514 | AB4: 0.02074322 | AC4: 0.333235 | AD4: 0.014613825 | AE4: 0.31949672 | AF4: 0.0051387145 | AG4: 0.34582917 | AH4: 0.022369933 | AI4: 0.2601328 | AJ4: 0.035028563 | AK4: 0.34263368 | AL4: 0.019418575 | AM4: 0.28771044 | AN4: 0.027488382
A5: 24 | B5: 1.5124757 | C5: 1.8013832 | D5: 18.624336 | E5: 0.82905874 | F5: 0.94728712 | G5: 10.110153 | H5: 0 | I5: 0 | J5: 0 | K5: 0 | L5: 1 | M5: 1 | N5: 0.8234932 | O5: 1 | P5: 0.81762175 | Q5: 1 | R5: 0.82730774 | S5: 1 | T5: 0.82154802 | U5: 1 | V5: 0 | W5: 1 | X5: 0 | Y5: 0.33521799 | Z5: 0.016558336 | AA5: 0.2887863 | AB5: 0.03493104 | AC5: 0.33237771 | AD5: 0.012881669 | AE5: 0.32519127 | AF5: 0.028787376 | AG5: 0.34016102 | AH5: 0.018815003 | AI5: 0.26243371 | AJ5: 0.044866083 | AK5: 0.33749924 | AL5: 0.016250659 | AM5: 0.28895641 | AN5: 0.0402752
A6: 30 | B6: 1.9881278 | C6: 2.3343295 | D6: 19.70826 | E6: 0.7811802 | F6: 0.87429369 | G6: 7.5751974 | H6: 0 | I6: 0 | J6: 0 | K6: 0 | L6: 1 | M6: 1 | N6: 0.82426772 | O6: 1 | P6: 0.81878387 | Q6: 1 | R6: 0.83088112 | S6: 1 | T6: 0.82548496 | U6: 1 | V6: 0 | W6: 1 | X6: 0 | Y6: 0.33932333 | Z6: 0.014999201 | AA6: 0.2807331 | AB6: 0.036825737 | AC6: 0.33626431 | AD6: 0.012191253 | AE6: 0.31857199 | AF6: 0.032081354 | AG6: 0.34797134 | AH6: 0.019370715 | AI6: 0.2566625 | AJ6: 0.045039727 | AK6: 0.34503508 | AL6: 0.018577299 | AM6: 0.28444451 | AN6: 0.042749187
A7: 36 | B7: 2.5869532 | C7: 2.9603225 | D7: 21.132876 | E7: 0.77818716 | F7: 0.85549585 | G7: 6.2209038 | H7: 0.02 | I7: 0.19899749 | J7: 0.02 | K7: 0.19899749 | L7: 0.99 | M7: 0.99846154 | N7: 0.82079659 | O7: 0.99947368 | P7: 0.81698346 | Q7: 0.99945946 | R7: 0.82686252 | S7: 0.99947368 | T7: 0.82314765 | U7: 0.99945946 | V7: 0.071748418 | W7: 0.95 | X7: 0.05 | Y7: 0.33514396 | Z7: 0.012242657 | AA7: 0.2822698 | AB7: 0.029518041 | AC7: 0.33330595 | AD7: 0.010367876 | AE7: 0.32373358 | AF7: 0.02294896 | AG7: 0.34342616 | AH7: 0.014741289 | AI7: 0.25364376 | AJ7: 0.041703042 | AK7: 0.34172841 | AL7: 0.014055243 | AM7: 0.28354503 | AN7: 0.039426574
A8: 42 | B8: 2.8497711 | C8: 3.2002857 | D8: 20.078473 | E8: 0.86115534 | F8: 0.9091722 | G8: 5.7458107 | H8: 0.07 | I8: 0.25514702 | J8: 0.078 | K8: 0.29650632 | L8: 0.93 | M8: 0.99464429 | N8: 0.81980514 | O8: 0.99822725 | P8: 0.81616643 | Q8: 0.99824018 | R8: 0.82758243 | S8: 0.99828017 | T8: 0.82414728 | U8: 0.99829311 | V8: 0.090376573 | W8: 0.9 | X8: 0.1 | Y8: 0.34052625 | Z8: 0.012066735 | AA8: 0.28238433 | AB8: 0.035522622 | AC8: 0.33833541 | AD8: 0.0099089427 | AE8: 0.32411945 | AF8: 0.029856075 | AG8: 0.35036958 | AH8: 0.01639966 | AI8: 0.25590491 | AJ8: 0.042857845 | AK8: 0.34847746 | AL8: 0.015565985 | AM8: 0.28660677 | AN8: 0.04090819
A9: 48 | B9: 3.2747527 | C9: 3.6453615 | D9: 20.292967 | E9: 0.93435121 | F9: 0.99988255 | G9: 5.5240485 | H9: 0.13 | I9: 0.39127995 | J9: 0.13 | K9: 0.39127995 | L9: 0.89 | M9: 0.99216912 | N9: 0.81911421 | O9: 0.99758968 | P9: 0.81513053 | Q9: 0.99748564 | R9: 0.82765489 | S9: 0.99758968 | T9: 0.82384843 | U9: 0.99748564 | V9: 0.17621228 | W9: 0.83 | X9: 0.17 | Y9: 0.3405038 | Z9: 0.012023035 | AA9: 0.28352433 | AB9: 0.032486167 | AC9: 0.3380913 | AD9: 0.010326031 | AE9: 0.32507433 | AF9: 0.02824168 | AG9: 0.3526664 | AH9: 0.01590747 | AI9: 0.25973403 | AJ9: 0.040300561 | AK9: 0.35048366 | AL9: 0.0162748 | AM9: 0.29087218 | AN9: 0.039597261
A10: 54 | B10: 3.8639602 | C10: 4.232338 | D10: 21.09661 | E10: 1.0283513 | F10: 1.1093478 | G10: 5.3235668 | H10: 0.25 | I10: 0.55452683 | J10: 0.2666 | K10: 0.57456457 | L10: 0.8007 | M10: 0.98562807 | N10: 0.81835818 | O10: 0.99528271 | P10: 0.81390404 | Q10: 0.99530886 | R10: 0.82444644 | S10: 0.99539272 | T10: 0.82014223 | U10: 0.9954177 | V10: 0.466575 | W10: 0.59 | X10: 0.41 | Y10: 0.33991586 | Z10: 0.010466799 | AA10: 0.28341634 | AB10: 0.033880782 | AC10: 0.33730598 | AD10: 0.008014025 | AE10: 0.32277426 | AF10: 0.027899992 | AG10: 0.34813372 | AH10: 0.014458874 | AI10: 0.25764149 | AJ10: 0.043772335 | AK10: 0.34576923 | AL10: 0.013740358 | AM10: 0.28653322 | AN10: 0.041537693
A11: 60 | B11: 4.2814521 | C11: 4.6780589 | D11: 21.09828 | E11: 0.85659371 | F11: 0.88408333 | G11: 3.8268933 | H11: 0.41 | I11: 0.73613857 | J11: 0.4553 | K11: 0.80312011 | L11: 0.6927 | M11: 0.97777533 | N11: 0.81485657 | O11: 0.99173558 | P11: 0.81139862 | Q11: 0.99256611 | R11: 0.82199256 | S11: 0.9920459 | T11: 0.81870039 | U11: 0.99286914 | V11: 0.72520836 | W11: 0.47 | X11: 0.53 | Y11: 0.3400057 | Z11: 0.010385261 | AA11: 0.28623881 | AB11: 0.034974593 | AC11: 0.3372294 | AD11: 0.0079470454 | AE11: 0.32643014 | AF11: 0.030139898 | AG11: 0.34924832 | AH11: 0.013914002 | AI11: 0.26010589 | AJ11: 0.041179942 | AK11: 0.34673848 | AL11: 0.0133143 | AM11: 0.28980188 | AN11: 0.039639987
A12: 66 | B12: 4.8462143 | C12: 5.2510107 | D12: 21.751523 | E12: 0.90995553 | F12: 0.91221755 | G12: 3.550157 | H12: 0.65 | I12: 0.80467385 | J12: 0.6773 | K12: 0.83580184 | L12: 0.5276 | M12: 0.96971765 | N12: 0.81422836 | O12: 0.98975385 | P12: 0.81011001 | Q12: 0.99002617 | R12: 0.82369475 | S12: 0.99022204 | T12: 0.81984653 | U12: 0.9905005 | V12: 1.061855 | W12: 0.28 | X12: 0.72 | Y12: 0.34288046 | Z12: 0.010325186 | AA12: 0.27608066 | AB12: 0.029612232 | AC12: 0.3393996 | AD12: 0.0081114255 | AE12: 0.31606359 | AF12: 0.024725097 | AG12: 0.356145 | AH12: 0.014853371 | AI12: 0.25637119 | AJ12: 0.03716228 | AK12: 0.3532355 | AL12: 0.015051115 | AM12: 0.28688423 | AN12: 0.036346516
A13: 72 | B13: 5.4179691 | C13: 5.8127854 | D13: 22.270861 | E13: 0.79264489 | F13: 0.813141 | G13: 2.9122873 | H13: 0.73 | I13: 0.97831488 | J13: 0.7864 | K13: 1.006566 | L13: 0.495 | M13: 0.96785186 | N13: 0.81343626 | O13: 0.98889078 | P13: 0.80930456 | Q13: 0.98941745 | R13: 0.82165578 | S13: 0.98933275 | T13: 0.8177203 | U13: 0.98982428 | V13: 1.1197186 | W13: 0.24 | X13: 0.76 | Y13: 0.34068534 | Z13: 0.008639818 | AA13: 0.28073992 | AB13: 0.034029974 | AC13: 0.33757045 | AD13: 0.0069770331 | AE13: 0.32126663 | AF13: 0.027773424 | AG13: 0.35212523 | AH13: 0.014260672 | AI13: 0.2586926 | AJ13: 0.044775299 | AK13: 0.34934455 | AL13: 0.014736964 | AM13: 0.28912706 | AN13: 0.043570015
... A21: 120 | B21: 8.7142584 | C21: 9.118775 | D21: 21.70623 | E21: 1.0772801 | F21: 1.0815072 | G21: 2.2118551 | H21: 1.75 | I21: 1.2031209 | J21: 1.8428 | K21: 1.2459888 | L21: 0.1755 | M21: 0.9541628 | N21: 0.80839365 | O21: 0.98455125 | P21: 0.80542157 | Q21: 0.98490972 | R21: 0.8198562 | S21: 0.98557494 | T21: 0.81718387 | U21: 0.98593969 | V21: 2.7062123 | W21: 0.01 | X21: 0.99 | Y21: 0.33993887 | Z21: 0.0088249465 | AA21: 0.2791235 | AB21: 0.030623714 | AC21: 0.33765243 | AD21: 0.0067680547 | AE21: 0.322467 | AF21: 0.027995875 | AG21: 0.35778638 | AH21: 0.0129317 | AI21: 0.25883812 | AJ21: 0.033302416 | AK21: 0.35614715 | AL21: 0.012763832 | AM21: 0.29213839 | AN21: 0.032827626

Sheet Case-6
A1: N | B1: MAE_Learn | C1: RMSE_Learn | D1: MAPE_Learn | E1: Standard_MAE_Learn | F1: Standard_RMSE_Learn | G1: Standard_MAPE_Learn | H1: np.mean(Z_SATSolver_index_list) | I1: np.std(Z_SATSolver_index_list) | J1: np.mean(Num_Solved_SAT) | K1: np.std(Num_Solved_SAT) | L1: Solved_SAT_Count / (Maxcomb * NumTrail) | M1: np.mean(Ratio_Solved_Component) | N1: np.mean(Ratio_Solved_Initial) | O1: np.mean(Ratio_Solved_Initial_Satisfied) | P1: np.mean(Ratio_Solved_Red) | Q1: np.mean(Ratio_Solved_Red_Satisfied) | R1: np.mean(Ratio_Solved_Tse) | S1: np.mean(Ratio_Solved_Tse_Satisfied) | T1: np.mean(Ratio_Solved_After) | U1: np.mean(Ratio_Solved_After_Satisfied) | V1: MAE_Energy | W1: Ratio of global minimum solutions | X1: Ratio of local minimum solutions | Y1: np.mean(Similarity_list_J_Initial) | Z1: np.std(Similarity_list_J_Initial) | AA1: np.mean(Similarity_list_H_Initial) | AB1: np.std(Similarity_list_H_Initial) | AC1: np.mean(Similarity_list_J_Red) | AD1: np.std(Similarity_list_J_Red) | AE1: np.mean(Similarity_list_H_Red) | AF1: np.std(Similarity_list_H_Red) | AG1: np.mean(Similarity_list_J_Tse) | AH1: np.std(Similarity_list_J_Tse) | AI1: np.mean(Similarity_list_H_Tse) | AJ1: np.std(Similarity_list_H_Tse) | AK1: np.mean(Similarity_list_J_After) | AL1: np.std(Similarity_list_J_After) | AM1: np.mean(Similarity_list_H_After) | AN1: np.std(Similarity_list_H_After)
A2: 6 | B2: 0.33983333 | C2: 0.43962443 | D2: 16.991667 | E2: 0.37272193 | F2: 0.47947579 | G2: 18.636097 | H2: 0 | I2: 0 | J2: 0 | K2: 0 | L2: 1 | M2: 1 | N2: 0.8 | O2: 1 | P2: 0.8 | Q2: 1 | R2: 0.8 | S2: 1 | T2: 0.8 | U2: 1 | V2: 0 | W2: 1 | X2: 0 | Y2: 0.31285333 | Z2: 0.012681937 | AA2: 0.5 | AB2: 0 | AC2: 0.31285333 | AD2: 0.012681937 | AE2: 0.5 | AF2: 0 | AG2: 0.31285333 | AH2: 0.012681937 | AI2: 0.5 | AJ2: 0 | AK2: 0.31285333 | AL2: 0.012681937 | AM2: 0.5 | AN2: 0
A3: 12 | B3: 0.70369841 | C3: 0.8842024 | D3: 17.59246 | E3: 0.56301365 | F3: 0.70065984 | G3: 14.075341 | H3: 0 | I3: 0 | J3: 0 | K3: 0 | L3: 1 | M3: 1 | N3: 0.8 | O3: 1 | P3: 0.8 | Q3: 1 | R3: 0.8 | S3: 1 | T3: 0.8 | U3: 1 | V3: 0 | W3: 1 | X3: 0 | Y3: 0.3236573 | Z3: 0.0087357716 | AA3: 0.5 | AB3: 0 | AC3: 0.3236573 | AD3: 0.0087357716 | AE3: 0.5 | AF3: 0 | AG3: 0.3236573 | AH3: 0.0087357716 | AI3: 0.5 | AJ3: 0 | AK3: 0.3236573 | AL3: 0.0087357716 | AM3: 0.5 | AN3: 0
A4: 18 | B4: 1.1614266 | C4: 1.4238256 | D4: 19.357111 | E4: 0.6368432 | F4: 0.76662522 | G4: 10.614053 | H4: 0 | I4: 0 | J4: 0 | K4: 0 | L4: 1 | M4: 1 | N4: 0.80875499 | O4: 1 | P4: 0.80569231 | Q4: 1 | R4: 0.80875499 | S4: 1 | T4: 0.80569231 | U4: 1 | V4: 0 | W4: 1 | X4: 0 | Y4: 0.33137353 | Z4: 0.013640914 | AA4: 0.41093863 | AB4: 0.054477645 | AC4: 0.32940776 | AD4: 0.0099669581 | AE4: 0.42994711 | AF4: 0.041765659 | AG4: 0.33137353 | AH4: 0.013640914 | AI4: 0.39744482 | AJ4: 0.068651739 | AK4: 0.32940776 | AL4: 0.0099669581 | AM4: 0.41364747 | AN4: 0.057661269
A5: 24 | B5: 1.6127868 | C5: 1.8997242 | D5: 20.159835 | E5: 0.74467208 | F5: 0.85739183 | G5: 9.308401 | H5: 0 | I5: 0 | J5: 0 | K5: 0 | L5: 1 | M5: 1 | N5: 0.80502402 | O5: 1 | P5: 0.8035 | Q5: 1 | R5: 0.80502402 | S5: 1 | T5: 0.8035 | U5: 1 | V5: 0 | W5: 1 | X5: 0 | Y5: 0.33023944 | Z5: 0.0094191607 | AA5: 0.43896473 | AB5: 0.047861654 | AC5: 0.32893307 | AD5: 0.0074690304 | AE5: 0.45396187 | AF5: 0.035441169 | AG5: 0.33023944 | AH5: 0.0094191607 | AI5: 0.42604647 | AJ5: 0.062007378 | AK5: 0.32893307 | AL5: 0.0074690304 | AM5: 0.43897349 | AN5: 0.051129474
A6: 30 | B6: 2.1478915 | C6: 2.4813562 | D6: 21.478915 | E6: 0.70246064 | F6: 0.78066347 | G6: 7.0246064 | H6: 0 | I6: 0 | J6: 0 | K6: 0 | L6: 1 | M6: 1 | N6: 0.80938288 | O6: 1 | P6: 0.80687992 | Q6: 1 | R6: 0.81128764 | S6: 1 | T6: 0.80878468 | U6: 1 | V6: 0 | W6: 1 | X6: 0 | Y6: 0.33401839 | Z6: 0.0095303529 | AA6: 0.38972967 | AB6: 0.05179557 | AC6: 0.33252205 | AD6: 0.0078228567 | AE6: 0.41511098 | AF6: 0.039732631 | AG6: 0.3364743 | AH6: 0.011492593 | AI6: 0.37069766 | AJ6: 0.063195593 | AK6: 0.33497796 | AL6: 0.010478496 | AM6: 0.39181486 | AN6: 0.053290711
A7: 36 | B7: 2.7130774 | C7: 3.1045695 | D7: 22.608979 | E7: 0.59743265 | F7: 0.6401331 | G7: 4.9786054 | H7: 0 | I7: 0 | J7: 0 | K7: 0 | L7: 1 | M7: 1 | N7: 0.80765504 | O7: 1 | P7: 0.80559066 | Q7: 1 | R7: 0.80975294 | S7: 1 | T7: 0.80768856 | U7: 1 | V7: 0.018052426 | W7: 0.98 | X7: 0.02 | Y7: 0.33327787 | Z7: 0.0084163414 | AA7: 0.4056704 | AB7: 0.047378001 | AC7: 0.331879 | AD7: 0.0065109199 | AE7: 0.42840285 | AF7: 0.035769405 | AG7: 0.33609704 | AH7: 0.010120951 | AI7: 0.38935228 | AJ7: 0.057307974 | AK7: 0.33469817 | AL7: 0.009048661 | AM7: 0.40884933 | AN7: 0.047332768
A8: 42 | B8: 3.262065 | C8: 3.6383275 | D8: 23.076085 | E8: 0.56072291 | F8: 0.62344652 | G8: 3.9345898 | H8: 0.09 | I8: 0.40236799 | J8: 0.09 | K8: 0.40236799 | L8: 0.94 | M8: 0.99371429 | N8: 0.80516092 | O8: 0.99826155 | P8: 0.80365871 | Q8: 0.99822309 | R8: 0.80614355 | S8: 0.99826155 | T8: 0.80464134 | U8: 0.99822309 | V8: 0.094210471 | W8: 0.87 | X8: 0.13 | Y8: 0.33361607 | Z8: 0.0079687246 | AA8: 0.41221488 | AB8: 0.050814924 | AC8: 0.33288018 | AD8: 0.0068580896 | AE8: 0.43442409 | AF8: 0.037546865 | AG8: 0.3349605 | AH8: 0.0087447491 | AI8: 0.39301914 | AJ8: 0.06558024 | AK8: 0.33422461 | AL8: 0.0078728749 | AM8: 0.4115196 | AN8: 0.055435308
A9: 48 | B9: 3.5199279 | C9: 3.9052219 | D9: 21.962021 | E9: 0.86024836 | F9: 0.92105438 | G9: 5.3355406 | H9: 0.25 | I9: 0.55452683 | J9: 0.2546 | K9: 0.55657779 | L9: 0.8054 | M9: 0.98416103 | N9: 0.80552249 | O9: 0.99549051 | P9: 0.80339376 | Q9: 0.99546987 | R9: 0.80850037 | S9: 0.99555509 | T9: 0.8063832 | U9: 0.99553478 | V9: 0.31246159 | W9: 0.72 | X9: 0.28 | Y9: 0.3347072 | Z9: 0.0080239136 | AA9: 0.38346838 | AB9: 0.041676884 | AC9: 0.33379586 | AD9: 0.0066395424 | AE9: 0.41209547 | AF9: 0.031417653 | AG9: 0.33858306 | AH9: 0.0098846869 | AI9: 0.36200427 | AJ9: 0.051650077 | AK9: 0.33767984 | AL9: 0.0092626348 | AM9: 0.38588103 | AN9: 0.043747044
A10: 54 | B10: 3.9894114 | C10: 4.3655601 | D10: 22.231904 | E10: 0.94176392 | F10: 1.0190751 | G10: 5.1915016 | H10: 0.48 | I10: 0.78076885 | J10: 0.4825 | K10: 0.78402407 | L10: 0.66 | M10: 0.9733114 | N10: 0.8013195 | O10: 0.99270685 | P10: 0.79963524 | Q10: 0.99265554 | R10: 0.80473082 | S10: 0.99278242 | T10: 0.80305571 | U10: 0.99273177 | V10: 0.57305531 | W10: 0.51 | X10: 0.49 | Y10: 0.334288 | Z10: 0.0063907986 | AA10: 0.40098688 | AB10: 0.046955197 | AC10: 0.33283126 | AD10: 0.0051277358 | AE10: 0.42587021 | AF10: 0.034803583 | AG10: 0.34011127 | AH10: 0.010312976 | AI10: 0.38640702 | AJ10: 0.05530777 | AK10: 0.33867277 | AL10: 0.010310278 | AM10: 0.4079942 | AN10: 0.045516905
A11: 60 | B11: 4.5658719 | C11: 4.9642828 | D11: 22.715614 | E11: 0.66688089 | F11: 0.69821764 | G11: 3.2516341 | H11: 0.64 | I11: 0.92217135 | J11: 0.6631 | K11: 0.94021189 | L11: 0.6018 | M11: 0.96693595 | N11: 0.80150118 | O11: 0.99060846 | P11: 0.79959473 | Q11: 0.9908143 | R11: 0.80422084 | S11: 0.99077384 | T11: 0.80233973 | U11: 0.99098274 | V11: 0.93864854 | W11: 0.38 | X11: 0.62 | Y11: 0.33578405 | Z11: 0.0067059099 | AA11: 0.38013735 | AB11: 0.037754525 | AC11: 0.3345108 | AD11: 0.005282083 | AE11: 0.40914427 | AF11: 0.028898495 | AG11: 0.33869064 | AH11: 0.0076618392 | AI11: 0.35720675 | AJ11: 0.047771008 | AK11: 0.33743495 | AL11: 0.0068368714 | AM11: 0.38126084 | AN11: 0.04097722
A12: 66 | B12: 5.0562424 | C12: 5.4406959 | D12: 22.930205 | E12: 0.79716741 | F12: 0.83354181 | G12: 3.4698989 | H12: 0.89 | I12: 1.0187738 | J12: 0.8997 | K12: 1.0200196 | L12: 0.4454 | M12: 0.95929276 | N12: 0.7982301 | O12: 0.98872647 | P12: 0.79697601 | Q12: 0.9887473 | R12: 0.80186747 | S12: 0.98891977 | T12: 0.80063518 | U12: 0.98893813 | V12: 1.3464298 | W12: 0.19 | X12: 0.81 | Y12: 0.33432773 | Z12: 0.0064463355 | AA12: 0.3879662 | AB12: 0.041100978 | AC12: 0.33325811 | AD12: 0.005361112 | AE12: 0.41738874 | AF12: 0.03066006 | AG12: 0.34040582 | AH12: 0.009350093 | AI12: 0.36670402 | AJ12: 0.048896305 | AK12: 0.33938028 | AL12: 0.008943694 | AM12: 0.39147948 | AN12: 0.041090751
A13: 72 | B13: 5.6685163 | C13: 6.0577974 | D13: 23.459645 | E13: 0.80091371 | F13: 0.8255249 | G13: 3.1566616 | H13: 1.01 | I13: 1.0816192 | J13: 1.0423 | K13: 1.0815317 | L13: 0.4006 | M13: 0.95688654 | N13: 0.79852543 | O13: 0.98777988 | P13: 0.79683391 | Q13: 0.98795426 | R13: 0.8015374 | S13: 0.98797377 | T13: 0.79986693 | U13: 0.98814695 | V13: 1.5539854 | W13: 0.11 | X13: 0.89 | Y13: 0.33577617 | Z13: 0.0067248156 | AA13: 0.38508101 | AB13: 0.026482258 | AC13: 0.3345468 | AD13: 0.0049776999 | AE13: 0.41381558 | AF13: 0.019806075 | AG13: 0.34045747 | AH13: 0.0076708611 | AI13: 0.36551432 | AJ13: 0.035309617 | AK13: 0.33926702 | AL13: 0.007049479 | AM13: 0.39012065 | AN13: 0.030840898
... A21: 120 | B21: 9.3961412 | C21: 9.7967334 | D21: 23.383141 | E21: 1.0500165 | F21: 1.0763926 | G21: 2.5260522 | H21: 1.98 | I21: 1.3926952 | J21: 2.0467 | K21: 1.4049623 | L21: 0.1269 | M21: 0.94904685 | N21: 0.79704912 | O21: 0.98541087 | P21: 0.79531554 | Q21: 0.98573805 | R21: 0.80025309 | S21: 0.98563418 | T21: 0.79856329 | U21: 0.98595887 | V21: 3.3564023 | W21: 0 | X21: 1 | Y21: 0.33746257 | Z21: 0.005751831 | AA21: 0.37317365 | AB21: 0.021256679 | AC21: 0.33520762 | AD21: 0.0042608988 | AE21: 0.40413827 | AF21: 0.014983461 | AG21: 0.34249126 | AH21: 0.0069852139 | AI21: 0.35273125 | AJ21: 0.03212617 | AK21: 0.34034443 | AL21: 0.0064149841 | AM21: 0.37890684 | AN21: 0.028616565

Sheet MAE_Learn
A1: N | B1: Case-1 | C1: Case-2 | D1: Case-3 | E1: Case-4 | F1: Case-5 | G1: Case-6
A2: 6 | B2: =VLOOKUP($A2,'Case-1'!$A$1:$AN$21,2,FALSE) -> 0.20692857 | C2: =VLOOKUP($A2,'Case-2'!$A$1:$AN$21,2,FALSE) -> 0.25666667 | D2: =VLOOKUP($A2,'Case-3'!$A$1:$AN$21,2,FALSE) -> 0.3085 | E2: =VLOOKUP($A2,'Case-4'!$A$1:$AN$21,2,FALSE) -> 0.27816667 | F2: =VLOOKUP($A2,'Case-5'!$A$1:$AN$21,2,FALSE) -> 0.3192619 | G2: =VLOOKUP($A2,'Case-6'!$A$1:$AN$21,2,FALSE) -> 0.33983333
A3: 12 | B3: =VLOOKUP($A3,'Case-1'!$A$1:$AN$21,2,FALSE) -> 0.58413636 | C3: =VLOOKUP($A3,'Case-2'!$A$1:$AN$21,2,FALSE) -> 0.58821762 | D3: =VLOOKUP($A3,'Case-3'!$A$1:$AN$21,2,FALSE) -> 0.62129315 | E3: =VLOOKUP($A3,'Case-4'!$A$1:$AN$21,2,FALSE) -> 0.62156396 | F3: =VLOOKUP($A3,'Case-5'!$A$1:$AN$21,2,FALSE) -> 0.65319841 | G3: =VLOOKUP($A3,'Case-6'!$A$1:$AN$21,2,FALSE) -> 0.70369841
A4: 18 | B4: =VLOOKUP($A4,'Case-1'!$A$1:$AN$21,2,FALSE) -> 0.9136269 | C4: =VLOOKUP($A4,'Case-2'!$A$1:$AN$21,2,FALSE) -> 0.86107126 | D4: =VLOOKUP($A4,'Case-3'!$A$1:$AN$21,2,FALSE) -> 0.94238849 | E4: =VLOOKUP($A4,'Case-4'!$A$1:$AN$21,2,FALSE) -> 1.0331965 | F4: =VLOOKUP($A4,'Case-5'!$A$1:$AN$21,2,FALSE) -> 1.0500885 | G4: =VLOOKUP($A4,'Case-6'!$A$1:$AN$21,2,FALSE) -> 1.1614266
A5: 24 | B5: =VLOOKUP($A5,'Case-1'!$A$1:$AN$21,2,FALSE) -> 1.2895562 | C5: =VLOOKUP($A5,'Case-2'!$A$1:$AN$21,2,FALSE) -> 1.3715089 | D5: =VLOOKUP($A5,'Case-3'!$A$1:$AN$21,2,FALSE) -> 1.3197431 | E5: =VLOOKUP($A5,'Case-4'!$A$1:$AN$21,2,FALSE) -> 1.2684104 | F5: =VLOOKUP($A5,'Case-5'!$A$1:$AN$21,2,FALSE) -> 1.5124757 | G5: =VLOOKUP($A5,'Case-6'!$A$1:$AN$21,2,FALSE) -> 1.6127868
A6: 30 | B6: =VLOOKUP($A6,'Case-1'!$A$1:$AN$21,2,FALSE) -> 1.7976594 | C6: =VLOOKUP($A6,'Case-2'!$A$1:$AN$21,2,FALSE) -> 1.8012147 | D6: =VLOOKUP($A6,'Case-3'!$A$1:$AN$21,2,FALSE) -> 1.639414 | E6: =VLOOKUP($A6,'Case-4'!$A$1:$AN$21,2,FALSE) -> 1.7322188 | F6: =VLOOKUP($A6,'Case-5'!$A$1:$AN$21,2,FALSE) -> 1.9881278 | G6: =VLOOKUP($A6,'Case-6'!$A$1:$AN$21,2,FALSE) -> 2.1478915
